2022-03-11 14:28:15,429 INFO server Server is running on localhost:7777
2022-03-11 14:28:15,630 ERROR server Timeout exceeded
Traceback (most recent call last):
  File "/home/ota_sms_user/client-server-apps/lesson_7/server.py", line 57, in main
    client, addr = s.accept()
  File "/usr/lib/python3.9/socket.py", line 293, in accept
    fd, addr = self._accept()
socket.timeout: timed out
2022-03-11 14:28:25,841 ERROR server Timeout exceeded
Traceback (most recent call last):
  File "/home/ota_sms_user/client-server-apps/lesson_7/server.py", line 57, in main
    client, addr = s.accept()
  File "/usr/lib/python3.9/socket.py", line 293, in accept
    fd, addr = self._accept()
socket.timeout: timed out
2022-03-11 14:28:36,052 ERROR server Timeout exceeded
Traceback (most recent call last):
  File "/home/ota_sms_user/client-server-apps/lesson_7/server.py", line 57, in main
    client, addr = s.accept()
  File "/usr/lib/python3.9/socket.py", line 293, in accept
    fd, addr = self._accept()
socket.timeout: timed out
2022-03-11 14:28:46,260 ERROR server Timeout exceeded
Traceback (most recent call last):
  File "/home/ota_sms_user/client-server-apps/lesson_7/server.py", line 57, in main
    client, addr = s.accept()
  File "/usr/lib/python3.9/socket.py", line 293, in accept
    fd, addr = self._accept()
socket.timeout: timed out
2022-03-11 14:28:56,471 ERROR server Timeout exceeded
Traceback (most recent call last):
  File "/home/ota_sms_user/client-server-apps/lesson_7/server.py", line 57, in main
    client, addr = s.accept()
  File "/usr/lib/python3.9/socket.py", line 293, in accept
    fd, addr = self._accept()
socket.timeout: timed out
2022-03-11 14:29:06,671 ERROR server Timeout exceeded
Traceback (most recent call last):
  File "/home/ota_sms_user/client-server-apps/lesson_7/server.py", line 57, in main
    client, addr = s.accept()
  File "/usr/lib/python3.9/socket.py", line 293, in accept
    fd, addr = self._accept()
socket.timeout: timed out
2022-03-11 14:29:16,880 ERROR server Timeout exceeded
Traceback (most recent call last):
  File "/home/ota_sms_user/client-server-apps/lesson_7/server.py", line 57, in main
    client, addr = s.accept()
  File "/usr/lib/python3.9/socket.py", line 293, in accept
    fd, addr = self._accept()
socket.timeout: timed out
2022-03-11 14:29:27,091 ERROR server Timeout exceeded
Traceback (most recent call last):
  File "/home/ota_sms_user/client-server-apps/lesson_7/server.py", line 57, in main
    client, addr = s.accept()
  File "/usr/lib/python3.9/socket.py", line 293, in accept
    fd, addr = self._accept()
socket.timeout: timed out
2022-03-11 14:29:37,302 ERROR server Timeout exceeded
Traceback (most recent call last):
  File "/home/ota_sms_user/client-server-apps/lesson_7/server.py", line 57, in main
    client, addr = s.accept()
  File "/usr/lib/python3.9/socket.py", line 293, in accept
    fd, addr = self._accept()
socket.timeout: timed out
2022-03-11 14:29:47,511 ERROR server Timeout exceeded
Traceback (most recent call last):
  File "/home/ota_sms_user/client-server-apps/lesson_7/server.py", line 57, in main
    client, addr = s.accept()
  File "/usr/lib/python3.9/socket.py", line 293, in accept
    fd, addr = self._accept()
socket.timeout: timed out
2022-03-11 14:29:57,720 ERROR server Timeout exceeded
Traceback (most recent call last):
  File "/home/ota_sms_user/client-server-apps/lesson_7/server.py", line 57, in main
    client, addr = s.accept()
  File "/usr/lib/python3.9/socket.py", line 293, in accept
    fd, addr = self._accept()
socket.timeout: timed out
2022-03-11 14:30:07,921 ERROR server Timeout exceeded
Traceback (most recent call last):
  File "/home/ota_sms_user/client-server-apps/lesson_7/server.py", line 57, in main
    client, addr = s.accept()
  File "/usr/lib/python3.9/socket.py", line 293, in accept
    fd, addr = self._accept()
socket.timeout: timed out
2022-03-11 14:30:18,132 ERROR server Timeout exceeded
Traceback (most recent call last):
  File "/home/ota_sms_user/client-server-apps/lesson_7/server.py", line 57, in main
    client, addr = s.accept()
  File "/usr/lib/python3.9/socket.py", line 293, in accept
    fd, addr = self._accept()
socket.timeout: timed out
2022-03-11 14:30:28,340 ERROR server Timeout exceeded
Traceback (most recent call last):
  File "/home/ota_sms_user/client-server-apps/lesson_7/server.py", line 57, in main
    client, addr = s.accept()
  File "/usr/lib/python3.9/socket.py", line 293, in accept
    fd, addr = self._accept()
socket.timeout: timed out
2022-03-11 14:30:38,552 ERROR server Timeout exceeded
Traceback (most recent call last):
  File "/home/ota_sms_user/client-server-apps/lesson_7/server.py", line 57, in main
    client, addr = s.accept()
  File "/usr/lib/python3.9/socket.py", line 293, in accept
    fd, addr = self._accept()
socket.timeout: timed out
2022-03-11 14:30:48,763 ERROR server Timeout exceeded
Traceback (most recent call last):
  File "/home/ota_sms_user/client-server-apps/lesson_7/server.py", line 57, in main
    client, addr = s.accept()
  File "/usr/lib/python3.9/socket.py", line 293, in accept
    fd, addr = self._accept()
socket.timeout: timed out
2022-03-11 14:30:58,975 ERROR server Timeout exceeded
Traceback (most recent call last):
  File "/home/ota_sms_user/client-server-apps/lesson_7/server.py", line 57, in main
    client, addr = s.accept()
  File "/usr/lib/python3.9/socket.py", line 293, in accept
    fd, addr = self._accept()
socket.timeout: timed out
2022-03-11 14:31:09,186 ERROR server Timeout exceeded
Traceback (most recent call last):
  File "/home/ota_sms_user/client-server-apps/lesson_7/server.py", line 57, in main
    client, addr = s.accept()
  File "/usr/lib/python3.9/socket.py", line 293, in accept
    fd, addr = self._accept()
socket.timeout: timed out
2022-03-11 14:31:19,396 ERROR server Timeout exceeded
Traceback (most recent call last):
  File "/home/ota_sms_user/client-server-apps/lesson_7/server.py", line 57, in main
    client, addr = s.accept()
  File "/usr/lib/python3.9/socket.py", line 293, in accept
    fd, addr = self._accept()
socket.timeout: timed out
2022-03-11 14:31:29,605 ERROR server Timeout exceeded
Traceback (most recent call last):
  File "/home/ota_sms_user/client-server-apps/lesson_7/server.py", line 57, in main
    client, addr = s.accept()
  File "/usr/lib/python3.9/socket.py", line 293, in accept
    fd, addr = self._accept()
socket.timeout: timed out
2022-03-11 14:31:39,816 ERROR server Timeout exceeded
Traceback (most recent call last):
  File "/home/ota_sms_user/client-server-apps/lesson_7/server.py", line 57, in main
    client, addr = s.accept()
  File "/usr/lib/python3.9/socket.py", line 293, in accept
    fd, addr = self._accept()
socket.timeout: timed out
2022-03-11 14:31:50,027 ERROR server Timeout exceeded
Traceback (most recent call last):
  File "/home/ota_sms_user/client-server-apps/lesson_7/server.py", line 57, in main
    client, addr = s.accept()
  File "/usr/lib/python3.9/socket.py", line 293, in accept
    fd, addr = self._accept()
socket.timeout: timed out
2022-03-11 14:32:00,236 ERROR server Timeout exceeded
Traceback (most recent call last):
  File "/home/ota_sms_user/client-server-apps/lesson_7/server.py", line 57, in main
    client, addr = s.accept()
  File "/usr/lib/python3.9/socket.py", line 293, in accept
    fd, addr = self._accept()
socket.timeout: timed out
2022-03-11 14:32:10,446 ERROR server Timeout exceeded
Traceback (most recent call last):
  File "/home/ota_sms_user/client-server-apps/lesson_7/server.py", line 57, in main
    client, addr = s.accept()
  File "/usr/lib/python3.9/socket.py", line 293, in accept
    fd, addr = self._accept()
socket.timeout: timed out
2022-03-11 14:32:20,651 ERROR server Timeout exceeded
Traceback (most recent call last):
  File "/home/ota_sms_user/client-server-apps/lesson_7/server.py", line 57, in main
    client, addr = s.accept()
  File "/usr/lib/python3.9/socket.py", line 293, in accept
    fd, addr = self._accept()
socket.timeout: timed out
2022-03-11 14:32:30,860 ERROR server Timeout exceeded
Traceback (most recent call last):
  File "/home/ota_sms_user/client-server-apps/lesson_7/server.py", line 57, in main
    client, addr = s.accept()
  File "/usr/lib/python3.9/socket.py", line 293, in accept
    fd, addr = self._accept()
socket.timeout: timed out
2022-03-11 14:32:41,072 ERROR server Timeout exceeded
Traceback (most recent call last):
  File "/home/ota_sms_user/client-server-apps/lesson_7/server.py", line 57, in main
    client, addr = s.accept()
  File "/usr/lib/python3.9/socket.py", line 293, in accept
    fd, addr = self._accept()
socket.timeout: timed out
2022-03-11 14:32:51,283 ERROR server Timeout exceeded
Traceback (most recent call last):
  File "/home/ota_sms_user/client-server-apps/lesson_7/server.py", line 57, in main
    client, addr = s.accept()
  File "/usr/lib/python3.9/socket.py", line 293, in accept
    fd, addr = self._accept()
socket.timeout: timed out
2022-03-11 14:33:01,491 ERROR server Timeout exceeded
Traceback (most recent call last):
  File "/home/ota_sms_user/client-server-apps/lesson_7/server.py", line 57, in main
    client, addr = s.accept()
  File "/usr/lib/python3.9/socket.py", line 293, in accept
    fd, addr = self._accept()
socket.timeout: timed out
2022-03-11 14:33:11,702 ERROR server Timeout exceeded
Traceback (most recent call last):
  File "/home/ota_sms_user/client-server-apps/lesson_7/server.py", line 57, in main
    client, addr = s.accept()
  File "/usr/lib/python3.9/socket.py", line 293, in accept
    fd, addr = self._accept()
socket.timeout: timed out
2022-03-11 14:33:21,911 ERROR server Timeout exceeded
Traceback (most recent call last):
  File "/home/ota_sms_user/client-server-apps/lesson_7/server.py", line 57, in main
    client, addr = s.accept()
  File "/usr/lib/python3.9/socket.py", line 293, in accept
    fd, addr = self._accept()
socket.timeout: timed out
2022-03-11 14:33:32,122 ERROR server Timeout exceeded
Traceback (most recent call last):
  File "/home/ota_sms_user/client-server-apps/lesson_7/server.py", line 57, in main
    client, addr = s.accept()
  File "/usr/lib/python3.9/socket.py", line 293, in accept
    fd, addr = self._accept()
socket.timeout: timed out
2022-03-11 14:33:42,329 ERROR server Timeout exceeded
Traceback (most recent call last):
  File "/home/ota_sms_user/client-server-apps/lesson_7/server.py", line 57, in main
    client, addr = s.accept()
  File "/usr/lib/python3.9/socket.py", line 293, in accept
    fd, addr = self._accept()
socket.timeout: timed out
2022-03-11 14:33:52,539 ERROR server Timeout exceeded
Traceback (most recent call last):
  File "/home/ota_sms_user/client-server-apps/lesson_7/server.py", line 57, in main
    client, addr = s.accept()
  File "/usr/lib/python3.9/socket.py", line 293, in accept
    fd, addr = self._accept()
socket.timeout: timed out
2022-03-11 14:34:02,751 ERROR server Timeout exceeded
Traceback (most recent call last):
  File "/home/ota_sms_user/client-server-apps/lesson_7/server.py", line 57, in main
    client, addr = s.accept()
  File "/usr/lib/python3.9/socket.py", line 293, in accept
    fd, addr = self._accept()
socket.timeout: timed out
2022-03-11 14:34:12,960 ERROR server Timeout exceeded
Traceback (most recent call last):
  File "/home/ota_sms_user/client-server-apps/lesson_7/server.py", line 57, in main
    client, addr = s.accept()
  File "/usr/lib/python3.9/socket.py", line 293, in accept
    fd, addr = self._accept()
socket.timeout: timed out
2022-03-11 14:34:23,172 ERROR server Timeout exceeded
Traceback (most recent call last):
  File "/home/ota_sms_user/client-server-apps/lesson_7/server.py", line 57, in main
    client, addr = s.accept()
  File "/usr/lib/python3.9/socket.py", line 293, in accept
    fd, addr = self._accept()
socket.timeout: timed out
2022-03-11 14:34:33,380 ERROR server Timeout exceeded
Traceback (most recent call last):
  File "/home/ota_sms_user/client-server-apps/lesson_7/server.py", line 57, in main
    client, addr = s.accept()
  File "/usr/lib/python3.9/socket.py", line 293, in accept
    fd, addr = self._accept()
socket.timeout: timed out
2022-03-11 14:34:43,591 ERROR server Timeout exceeded
Traceback (most recent call last):
  File "/home/ota_sms_user/client-server-apps/lesson_7/server.py", line 57, in main
    client, addr = s.accept()
  File "/usr/lib/python3.9/socket.py", line 293, in accept
    fd, addr = self._accept()
socket.timeout: timed out
2022-03-11 14:34:53,802 ERROR server Timeout exceeded
Traceback (most recent call last):
  File "/home/ota_sms_user/client-server-apps/lesson_7/server.py", line 57, in main
    client, addr = s.accept()
  File "/usr/lib/python3.9/socket.py", line 293, in accept
    fd, addr = self._accept()
socket.timeout: timed out
2022-03-11 14:35:04,013 ERROR server Timeout exceeded
Traceback (most recent call last):
  File "/home/ota_sms_user/client-server-apps/lesson_7/server.py", line 57, in main
    client, addr = s.accept()
  File "/usr/lib/python3.9/socket.py", line 293, in accept
    fd, addr = self._accept()
socket.timeout: timed out
2022-03-11 14:35:14,224 ERROR server Timeout exceeded
Traceback (most recent call last):
  File "/home/ota_sms_user/client-server-apps/lesson_7/server.py", line 57, in main
    client, addr = s.accept()
  File "/usr/lib/python3.9/socket.py", line 293, in accept
    fd, addr = self._accept()
socket.timeout: timed out
2022-03-11 14:35:24,425 ERROR server Timeout exceeded
Traceback (most recent call last):
  File "/home/ota_sms_user/client-server-apps/lesson_7/server.py", line 57, in main
    client, addr = s.accept()
  File "/usr/lib/python3.9/socket.py", line 293, in accept
    fd, addr = self._accept()
socket.timeout: timed out
2022-03-11 14:35:34,636 ERROR server Timeout exceeded
Traceback (most recent call last):
  File "/home/ota_sms_user/client-server-apps/lesson_7/server.py", line 57, in main
    client, addr = s.accept()
  File "/usr/lib/python3.9/socket.py", line 293, in accept
    fd, addr = self._accept()
socket.timeout: timed out
2022-03-11 14:35:44,844 ERROR server Timeout exceeded
Traceback (most recent call last):
  File "/home/ota_sms_user/client-server-apps/lesson_7/server.py", line 57, in main
    client, addr = s.accept()
  File "/usr/lib/python3.9/socket.py", line 293, in accept
    fd, addr = self._accept()
socket.timeout: timed out
2022-03-11 14:35:55,052 ERROR server Timeout exceeded
Traceback (most recent call last):
  File "/home/ota_sms_user/client-server-apps/lesson_7/server.py", line 57, in main
    client, addr = s.accept()
  File "/usr/lib/python3.9/socket.py", line 293, in accept
    fd, addr = self._accept()
socket.timeout: timed out
2022-03-11 14:36:05,263 ERROR server Timeout exceeded
Traceback (most recent call last):
  File "/home/ota_sms_user/client-server-apps/lesson_7/server.py", line 57, in main
    client, addr = s.accept()
  File "/usr/lib/python3.9/socket.py", line 293, in accept
    fd, addr = self._accept()
socket.timeout: timed out
2022-03-11 14:36:15,473 ERROR server Timeout exceeded
Traceback (most recent call last):
  File "/home/ota_sms_user/client-server-apps/lesson_7/server.py", line 57, in main
    client, addr = s.accept()
  File "/usr/lib/python3.9/socket.py", line 293, in accept
    fd, addr = self._accept()
socket.timeout: timed out
2022-03-11 14:36:25,684 ERROR server Timeout exceeded
Traceback (most recent call last):
  File "/home/ota_sms_user/client-server-apps/lesson_7/server.py", line 57, in main
    client, addr = s.accept()
  File "/usr/lib/python3.9/socket.py", line 293, in accept
    fd, addr = self._accept()
socket.timeout: timed out
2022-03-11 14:36:35,893 ERROR server Timeout exceeded
Traceback (most recent call last):
  File "/home/ota_sms_user/client-server-apps/lesson_7/server.py", line 57, in main
    client, addr = s.accept()
  File "/usr/lib/python3.9/socket.py", line 293, in accept
    fd, addr = self._accept()
socket.timeout: timed out
2022-03-11 14:36:46,095 ERROR server Timeout exceeded
Traceback (most recent call last):
  File "/home/ota_sms_user/client-server-apps/lesson_7/server.py", line 57, in main
    client, addr = s.accept()
  File "/usr/lib/python3.9/socket.py", line 293, in accept
    fd, addr = self._accept()
socket.timeout: timed out
2022-03-11 14:36:56,306 ERROR server Timeout exceeded
Traceback (most recent call last):
  File "/home/ota_sms_user/client-server-apps/lesson_7/server.py", line 57, in main
    client, addr = s.accept()
  File "/usr/lib/python3.9/socket.py", line 293, in accept
    fd, addr = self._accept()
socket.timeout: timed out
2022-03-11 14:37:06,516 ERROR server Timeout exceeded
Traceback (most recent call last):
  File "/home/ota_sms_user/client-server-apps/lesson_7/server.py", line 57, in main
    client, addr = s.accept()
  File "/usr/lib/python3.9/socket.py", line 293, in accept
    fd, addr = self._accept()
socket.timeout: timed out
2022-03-11 14:37:16,717 ERROR server Timeout exceeded
Traceback (most recent call last):
  File "/home/ota_sms_user/client-server-apps/lesson_7/server.py", line 57, in main
    client, addr = s.accept()
  File "/usr/lib/python3.9/socket.py", line 293, in accept
    fd, addr = self._accept()
socket.timeout: timed out
2022-03-11 14:37:26,928 ERROR server Timeout exceeded
Traceback (most recent call last):
  File "/home/ota_sms_user/client-server-apps/lesson_7/server.py", line 57, in main
    client, addr = s.accept()
  File "/usr/lib/python3.9/socket.py", line 293, in accept
    fd, addr = self._accept()
socket.timeout: timed out
2022-03-11 14:37:37,136 ERROR server Timeout exceeded
Traceback (most recent call last):
  File "/home/ota_sms_user/client-server-apps/lesson_7/server.py", line 57, in main
    client, addr = s.accept()
  File "/usr/lib/python3.9/socket.py", line 293, in accept
    fd, addr = self._accept()
socket.timeout: timed out
2022-03-11 14:37:47,341 ERROR server Timeout exceeded
Traceback (most recent call last):
  File "/home/ota_sms_user/client-server-apps/lesson_7/server.py", line 57, in main
    client, addr = s.accept()
  File "/usr/lib/python3.9/socket.py", line 293, in accept
    fd, addr = self._accept()
socket.timeout: timed out
2022-03-11 14:37:57,552 ERROR server Timeout exceeded
Traceback (most recent call last):
  File "/home/ota_sms_user/client-server-apps/lesson_7/server.py", line 57, in main
    client, addr = s.accept()
  File "/usr/lib/python3.9/socket.py", line 293, in accept
    fd, addr = self._accept()
socket.timeout: timed out
2022-03-11 14:38:07,763 ERROR server Timeout exceeded
Traceback (most recent call last):
  File "/home/ota_sms_user/client-server-apps/lesson_7/server.py", line 57, in main
    client, addr = s.accept()
  File "/usr/lib/python3.9/socket.py", line 293, in accept
    fd, addr = self._accept()
socket.timeout: timed out
2022-03-11 14:38:17,972 ERROR server Timeout exceeded
Traceback (most recent call last):
  File "/home/ota_sms_user/client-server-apps/lesson_7/server.py", line 57, in main
    client, addr = s.accept()
  File "/usr/lib/python3.9/socket.py", line 293, in accept
    fd, addr = self._accept()
socket.timeout: timed out
2022-03-11 14:38:28,183 ERROR server Timeout exceeded
Traceback (most recent call last):
  File "/home/ota_sms_user/client-server-apps/lesson_7/server.py", line 57, in main
    client, addr = s.accept()
  File "/usr/lib/python3.9/socket.py", line 293, in accept
    fd, addr = self._accept()
socket.timeout: timed out
2022-03-11 14:38:38,394 ERROR server Timeout exceeded
Traceback (most recent call last):
  File "/home/ota_sms_user/client-server-apps/lesson_7/server.py", line 57, in main
    client, addr = s.accept()
  File "/usr/lib/python3.9/socket.py", line 293, in accept
    fd, addr = self._accept()
socket.timeout: timed out
2022-03-11 14:38:48,601 ERROR server Timeout exceeded
Traceback (most recent call last):
  File "/home/ota_sms_user/client-server-apps/lesson_7/server.py", line 57, in main
    client, addr = s.accept()
  File "/usr/lib/python3.9/socket.py", line 293, in accept
    fd, addr = self._accept()
socket.timeout: timed out
2022-03-11 14:38:58,802 ERROR server Timeout exceeded
Traceback (most recent call last):
  File "/home/ota_sms_user/client-server-apps/lesson_7/server.py", line 57, in main
    client, addr = s.accept()
  File "/usr/lib/python3.9/socket.py", line 293, in accept
    fd, addr = self._accept()
socket.timeout: timed out
2022-03-11 14:39:09,013 ERROR server Timeout exceeded
Traceback (most recent call last):
  File "/home/ota_sms_user/client-server-apps/lesson_7/server.py", line 57, in main
    client, addr = s.accept()
  File "/usr/lib/python3.9/socket.py", line 293, in accept
    fd, addr = self._accept()
socket.timeout: timed out
2022-03-11 14:39:19,224 ERROR server Timeout exceeded
Traceback (most recent call last):
  File "/home/ota_sms_user/client-server-apps/lesson_7/server.py", line 57, in main
    client, addr = s.accept()
  File "/usr/lib/python3.9/socket.py", line 293, in accept
    fd, addr = self._accept()
socket.timeout: timed out
2022-03-11 14:39:29,432 ERROR server Timeout exceeded
Traceback (most recent call last):
  File "/home/ota_sms_user/client-server-apps/lesson_7/server.py", line 57, in main
    client, addr = s.accept()
  File "/usr/lib/python3.9/socket.py", line 293, in accept
    fd, addr = self._accept()
socket.timeout: timed out
2022-03-11 14:39:39,642 ERROR server Timeout exceeded
Traceback (most recent call last):
  File "/home/ota_sms_user/client-server-apps/lesson_7/server.py", line 57, in main
    client, addr = s.accept()
  File "/usr/lib/python3.9/socket.py", line 293, in accept
    fd, addr = self._accept()
socket.timeout: timed out
2022-03-11 14:39:49,852 ERROR server Timeout exceeded
Traceback (most recent call last):
  File "/home/ota_sms_user/client-server-apps/lesson_7/server.py", line 57, in main
    client, addr = s.accept()
  File "/usr/lib/python3.9/socket.py", line 293, in accept
    fd, addr = self._accept()
socket.timeout: timed out
2022-03-11 14:40:00,059 ERROR server Timeout exceeded
Traceback (most recent call last):
  File "/home/ota_sms_user/client-server-apps/lesson_7/server.py", line 57, in main
    client, addr = s.accept()
  File "/usr/lib/python3.9/socket.py", line 293, in accept
    fd, addr = self._accept()
socket.timeout: timed out
2022-03-11 14:40:10,271 ERROR server Timeout exceeded
Traceback (most recent call last):
  File "/home/ota_sms_user/client-server-apps/lesson_7/server.py", line 57, in main
    client, addr = s.accept()
  File "/usr/lib/python3.9/socket.py", line 293, in accept
    fd, addr = self._accept()
socket.timeout: timed out
2022-03-11 14:40:20,480 ERROR server Timeout exceeded
Traceback (most recent call last):
  File "/home/ota_sms_user/client-server-apps/lesson_7/server.py", line 57, in main
    client, addr = s.accept()
  File "/usr/lib/python3.9/socket.py", line 293, in accept
    fd, addr = self._accept()
socket.timeout: timed out
2022-03-11 14:40:30,691 ERROR server Timeout exceeded
Traceback (most recent call last):
  File "/home/ota_sms_user/client-server-apps/lesson_7/server.py", line 57, in main
    client, addr = s.accept()
  File "/usr/lib/python3.9/socket.py", line 293, in accept
    fd, addr = self._accept()
socket.timeout: timed out
2022-03-11 14:40:40,900 ERROR server Timeout exceeded
Traceback (most recent call last):
  File "/home/ota_sms_user/client-server-apps/lesson_7/server.py", line 57, in main
    client, addr = s.accept()
  File "/usr/lib/python3.9/socket.py", line 293, in accept
    fd, addr = self._accept()
socket.timeout: timed out
2022-03-11 14:40:51,108 ERROR server Timeout exceeded
Traceback (most recent call last):
  File "/home/ota_sms_user/client-server-apps/lesson_7/server.py", line 57, in main
    client, addr = s.accept()
  File "/usr/lib/python3.9/socket.py", line 293, in accept
    fd, addr = self._accept()
socket.timeout: timed out
2022-03-11 14:41:01,316 ERROR server Timeout exceeded
Traceback (most recent call last):
  File "/home/ota_sms_user/client-server-apps/lesson_7/server.py", line 57, in main
    client, addr = s.accept()
  File "/usr/lib/python3.9/socket.py", line 293, in accept
    fd, addr = self._accept()
socket.timeout: timed out
2022-03-11 14:41:11,523 ERROR server Timeout exceeded
Traceback (most recent call last):
  File "/home/ota_sms_user/client-server-apps/lesson_7/server.py", line 57, in main
    client, addr = s.accept()
  File "/usr/lib/python3.9/socket.py", line 293, in accept
    fd, addr = self._accept()
socket.timeout: timed out
2022-03-11 14:41:21,734 ERROR server Timeout exceeded
Traceback (most recent call last):
  File "/home/ota_sms_user/client-server-apps/lesson_7/server.py", line 57, in main
    client, addr = s.accept()
  File "/usr/lib/python3.9/socket.py", line 293, in accept
    fd, addr = self._accept()
socket.timeout: timed out
2022-03-11 14:41:31,936 ERROR server Timeout exceeded
Traceback (most recent call last):
  File "/home/ota_sms_user/client-server-apps/lesson_7/server.py", line 57, in main
    client, addr = s.accept()
  File "/usr/lib/python3.9/socket.py", line 293, in accept
    fd, addr = self._accept()
socket.timeout: timed out
2022-03-11 14:41:42,144 ERROR server Timeout exceeded
Traceback (most recent call last):
  File "/home/ota_sms_user/client-server-apps/lesson_7/server.py", line 57, in main
    client, addr = s.accept()
  File "/usr/lib/python3.9/socket.py", line 293, in accept
    fd, addr = self._accept()
socket.timeout: timed out
2022-03-11 14:41:52,355 ERROR server Timeout exceeded
Traceback (most recent call last):
  File "/home/ota_sms_user/client-server-apps/lesson_7/server.py", line 57, in main
    client, addr = s.accept()
  File "/usr/lib/python3.9/socket.py", line 293, in accept
    fd, addr = self._accept()
socket.timeout: timed out
2022-03-11 14:42:02,567 ERROR server Timeout exceeded
Traceback (most recent call last):
  File "/home/ota_sms_user/client-server-apps/lesson_7/server.py", line 57, in main
    client, addr = s.accept()
  File "/usr/lib/python3.9/socket.py", line 293, in accept
    fd, addr = self._accept()
socket.timeout: timed out
2022-03-11 14:42:12,768 ERROR server Timeout exceeded
Traceback (most recent call last):
  File "/home/ota_sms_user/client-server-apps/lesson_7/server.py", line 57, in main
    client, addr = s.accept()
  File "/usr/lib/python3.9/socket.py", line 293, in accept
    fd, addr = self._accept()
socket.timeout: timed out
2022-03-11 14:42:22,979 ERROR server Timeout exceeded
Traceback (most recent call last):
  File "/home/ota_sms_user/client-server-apps/lesson_7/server.py", line 57, in main
    client, addr = s.accept()
  File "/usr/lib/python3.9/socket.py", line 293, in accept
    fd, addr = self._accept()
socket.timeout: timed out
2022-03-11 14:42:33,190 ERROR server Timeout exceeded
Traceback (most recent call last):
  File "/home/ota_sms_user/client-server-apps/lesson_7/server.py", line 57, in main
    client, addr = s.accept()
  File "/usr/lib/python3.9/socket.py", line 293, in accept
    fd, addr = self._accept()
socket.timeout: timed out
2022-03-11 14:42:43,400 ERROR server Timeout exceeded
Traceback (most recent call last):
  File "/home/ota_sms_user/client-server-apps/lesson_7/server.py", line 57, in main
    client, addr = s.accept()
  File "/usr/lib/python3.9/socket.py", line 293, in accept
    fd, addr = self._accept()
socket.timeout: timed out
2022-03-11 14:42:53,608 ERROR server Timeout exceeded
Traceback (most recent call last):
  File "/home/ota_sms_user/client-server-apps/lesson_7/server.py", line 57, in main
    client, addr = s.accept()
  File "/usr/lib/python3.9/socket.py", line 293, in accept
    fd, addr = self._accept()
socket.timeout: timed out
2022-03-11 14:43:03,816 ERROR server Timeout exceeded
Traceback (most recent call last):
  File "/home/ota_sms_user/client-server-apps/lesson_7/server.py", line 57, in main
    client, addr = s.accept()
  File "/usr/lib/python3.9/socket.py", line 293, in accept
    fd, addr = self._accept()
socket.timeout: timed out
2022-03-11 14:43:14,025 ERROR server Timeout exceeded
Traceback (most recent call last):
  File "/home/ota_sms_user/client-server-apps/lesson_7/server.py", line 57, in main
    client, addr = s.accept()
  File "/usr/lib/python3.9/socket.py", line 293, in accept
    fd, addr = self._accept()
socket.timeout: timed out
2022-03-11 14:43:24,236 ERROR server Timeout exceeded
Traceback (most recent call last):
  File "/home/ota_sms_user/client-server-apps/lesson_7/server.py", line 57, in main
    client, addr = s.accept()
  File "/usr/lib/python3.9/socket.py", line 293, in accept
    fd, addr = self._accept()
socket.timeout: timed out
2022-03-11 14:43:34,444 ERROR server Timeout exceeded
Traceback (most recent call last):
  File "/home/ota_sms_user/client-server-apps/lesson_7/server.py", line 57, in main
    client, addr = s.accept()
  File "/usr/lib/python3.9/socket.py", line 293, in accept
    fd, addr = self._accept()
socket.timeout: timed out
2022-03-11 14:43:44,653 ERROR server Timeout exceeded
Traceback (most recent call last):
  File "/home/ota_sms_user/client-server-apps/lesson_7/server.py", line 57, in main
    client, addr = s.accept()
  File "/usr/lib/python3.9/socket.py", line 293, in accept
    fd, addr = self._accept()
socket.timeout: timed out
2022-03-11 14:43:54,864 ERROR server Timeout exceeded
Traceback (most recent call last):
  File "/home/ota_sms_user/client-server-apps/lesson_7/server.py", line 57, in main
    client, addr = s.accept()
  File "/usr/lib/python3.9/socket.py", line 293, in accept
    fd, addr = self._accept()
socket.timeout: timed out
2022-03-11 14:44:05,070 ERROR server Timeout exceeded
Traceback (most recent call last):
  File "/home/ota_sms_user/client-server-apps/lesson_7/server.py", line 57, in main
    client, addr = s.accept()
  File "/usr/lib/python3.9/socket.py", line 293, in accept
    fd, addr = self._accept()
socket.timeout: timed out
2022-03-11 14:44:15,280 ERROR server Timeout exceeded
Traceback (most recent call last):
  File "/home/ota_sms_user/client-server-apps/lesson_7/server.py", line 57, in main
    client, addr = s.accept()
  File "/usr/lib/python3.9/socket.py", line 293, in accept
    fd, addr = self._accept()
socket.timeout: timed out
2022-03-11 14:44:25,489 ERROR server Timeout exceeded
Traceback (most recent call last):
  File "/home/ota_sms_user/client-server-apps/lesson_7/server.py", line 57, in main
    client, addr = s.accept()
  File "/usr/lib/python3.9/socket.py", line 293, in accept
    fd, addr = self._accept()
socket.timeout: timed out
2022-03-11 14:44:35,700 ERROR server Timeout exceeded
Traceback (most recent call last):
  File "/home/ota_sms_user/client-server-apps/lesson_7/server.py", line 57, in main
    client, addr = s.accept()
  File "/usr/lib/python3.9/socket.py", line 293, in accept
    fd, addr = self._accept()
socket.timeout: timed out
2022-03-11 14:44:45,908 ERROR server Timeout exceeded
Traceback (most recent call last):
  File "/home/ota_sms_user/client-server-apps/lesson_7/server.py", line 57, in main
    client, addr = s.accept()
  File "/usr/lib/python3.9/socket.py", line 293, in accept
    fd, addr = self._accept()
socket.timeout: timed out
2022-03-11 14:44:56,116 ERROR server Timeout exceeded
Traceback (most recent call last):
  File "/home/ota_sms_user/client-server-apps/lesson_7/server.py", line 57, in main
    client, addr = s.accept()
  File "/usr/lib/python3.9/socket.py", line 293, in accept
    fd, addr = self._accept()
socket.timeout: timed out
2022-03-11 14:45:06,327 ERROR server Timeout exceeded
Traceback (most recent call last):
  File "/home/ota_sms_user/client-server-apps/lesson_7/server.py", line 57, in main
    client, addr = s.accept()
  File "/usr/lib/python3.9/socket.py", line 293, in accept
    fd, addr = self._accept()
socket.timeout: timed out
2022-03-11 14:45:16,537 ERROR server Timeout exceeded
Traceback (most recent call last):
  File "/home/ota_sms_user/client-server-apps/lesson_7/server.py", line 57, in main
    client, addr = s.accept()
  File "/usr/lib/python3.9/socket.py", line 293, in accept
    fd, addr = self._accept()
socket.timeout: timed out
2022-03-11 14:45:26,744 ERROR server Timeout exceeded
Traceback (most recent call last):
  File "/home/ota_sms_user/client-server-apps/lesson_7/server.py", line 57, in main
    client, addr = s.accept()
  File "/usr/lib/python3.9/socket.py", line 293, in accept
    fd, addr = self._accept()
socket.timeout: timed out
2022-03-11 14:45:36,952 ERROR server Timeout exceeded
Traceback (most recent call last):
  File "/home/ota_sms_user/client-server-apps/lesson_7/server.py", line 57, in main
    client, addr = s.accept()
  File "/usr/lib/python3.9/socket.py", line 293, in accept
    fd, addr = self._accept()
socket.timeout: timed out
2022-03-11 14:45:47,163 ERROR server Timeout exceeded
Traceback (most recent call last):
  File "/home/ota_sms_user/client-server-apps/lesson_7/server.py", line 57, in main
    client, addr = s.accept()
  File "/usr/lib/python3.9/socket.py", line 293, in accept
    fd, addr = self._accept()
socket.timeout: timed out
2022-03-11 14:45:57,372 ERROR server Timeout exceeded
Traceback (most recent call last):
  File "/home/ota_sms_user/client-server-apps/lesson_7/server.py", line 57, in main
    client, addr = s.accept()
  File "/usr/lib/python3.9/socket.py", line 293, in accept
    fd, addr = self._accept()
socket.timeout: timed out
2022-03-11 14:46:07,580 ERROR server Timeout exceeded
Traceback (most recent call last):
  File "/home/ota_sms_user/client-server-apps/lesson_7/server.py", line 57, in main
    client, addr = s.accept()
  File "/usr/lib/python3.9/socket.py", line 293, in accept
    fd, addr = self._accept()
socket.timeout: timed out
2022-03-11 14:46:17,788 ERROR server Timeout exceeded
Traceback (most recent call last):
  File "/home/ota_sms_user/client-server-apps/lesson_7/server.py", line 57, in main
    client, addr = s.accept()
  File "/usr/lib/python3.9/socket.py", line 293, in accept
    fd, addr = self._accept()
socket.timeout: timed out
2022-03-11 14:46:27,999 ERROR server Timeout exceeded
Traceback (most recent call last):
  File "/home/ota_sms_user/client-server-apps/lesson_7/server.py", line 57, in main
    client, addr = s.accept()
  File "/usr/lib/python3.9/socket.py", line 293, in accept
    fd, addr = self._accept()
socket.timeout: timed out
2022-03-11 14:46:38,208 ERROR server Timeout exceeded
Traceback (most recent call last):
  File "/home/ota_sms_user/client-server-apps/lesson_7/server.py", line 57, in main
    client, addr = s.accept()
  File "/usr/lib/python3.9/socket.py", line 293, in accept
    fd, addr = self._accept()
socket.timeout: timed out
2022-03-11 14:46:48,416 ERROR server Timeout exceeded
Traceback (most recent call last):
  File "/home/ota_sms_user/client-server-apps/lesson_7/server.py", line 57, in main
    client, addr = s.accept()
  File "/usr/lib/python3.9/socket.py", line 293, in accept
    fd, addr = self._accept()
socket.timeout: timed out
2022-03-11 14:46:58,624 ERROR server Timeout exceeded
Traceback (most recent call last):
  File "/home/ota_sms_user/client-server-apps/lesson_7/server.py", line 57, in main
    client, addr = s.accept()
  File "/usr/lib/python3.9/socket.py", line 293, in accept
    fd, addr = self._accept()
socket.timeout: timed out
2022-03-11 14:47:08,834 ERROR server Timeout exceeded
Traceback (most recent call last):
  File "/home/ota_sms_user/client-server-apps/lesson_7/server.py", line 57, in main
    client, addr = s.accept()
  File "/usr/lib/python3.9/socket.py", line 293, in accept
    fd, addr = self._accept()
socket.timeout: timed out
2022-03-11 14:47:19,044 ERROR server Timeout exceeded
Traceback (most recent call last):
  File "/home/ota_sms_user/client-server-apps/lesson_7/server.py", line 57, in main
    client, addr = s.accept()
  File "/usr/lib/python3.9/socket.py", line 293, in accept
    fd, addr = self._accept()
socket.timeout: timed out
2022-03-11 14:47:29,256 ERROR server Timeout exceeded
Traceback (most recent call last):
  File "/home/ota_sms_user/client-server-apps/lesson_7/server.py", line 57, in main
    client, addr = s.accept()
  File "/usr/lib/python3.9/socket.py", line 293, in accept
    fd, addr = self._accept()
socket.timeout: timed out
2022-03-11 14:47:39,464 ERROR server Timeout exceeded
Traceback (most recent call last):
  File "/home/ota_sms_user/client-server-apps/lesson_7/server.py", line 57, in main
    client, addr = s.accept()
  File "/usr/lib/python3.9/socket.py", line 293, in accept
    fd, addr = self._accept()
socket.timeout: timed out
2022-03-11 14:47:49,675 ERROR server Timeout exceeded
Traceback (most recent call last):
  File "/home/ota_sms_user/client-server-apps/lesson_7/server.py", line 57, in main
    client, addr = s.accept()
  File "/usr/lib/python3.9/socket.py", line 293, in accept
    fd, addr = self._accept()
socket.timeout: timed out
2022-03-11 14:47:59,884 ERROR server Timeout exceeded
Traceback (most recent call last):
  File "/home/ota_sms_user/client-server-apps/lesson_7/server.py", line 57, in main
    client, addr = s.accept()
  File "/usr/lib/python3.9/socket.py", line 293, in accept
    fd, addr = self._accept()
socket.timeout: timed out
2022-03-11 14:48:10,095 ERROR server Timeout exceeded
Traceback (most recent call last):
  File "/home/ota_sms_user/client-server-apps/lesson_7/server.py", line 57, in main
    client, addr = s.accept()
  File "/usr/lib/python3.9/socket.py", line 293, in accept
    fd, addr = self._accept()
socket.timeout: timed out
2022-03-11 14:48:20,304 ERROR server Timeout exceeded
Traceback (most recent call last):
  File "/home/ota_sms_user/client-server-apps/lesson_7/server.py", line 57, in main
    client, addr = s.accept()
  File "/usr/lib/python3.9/socket.py", line 293, in accept
    fd, addr = self._accept()
socket.timeout: timed out
2022-03-11 14:48:30,512 ERROR server Timeout exceeded
Traceback (most recent call last):
  File "/home/ota_sms_user/client-server-apps/lesson_7/server.py", line 57, in main
    client, addr = s.accept()
  File "/usr/lib/python3.9/socket.py", line 293, in accept
    fd, addr = self._accept()
socket.timeout: timed out
2022-03-11 14:48:40,720 ERROR server Timeout exceeded
Traceback (most recent call last):
  File "/home/ota_sms_user/client-server-apps/lesson_7/server.py", line 57, in main
    client, addr = s.accept()
  File "/usr/lib/python3.9/socket.py", line 293, in accept
    fd, addr = self._accept()
socket.timeout: timed out
2022-03-11 14:48:50,928 ERROR server Timeout exceeded
Traceback (most recent call last):
  File "/home/ota_sms_user/client-server-apps/lesson_7/server.py", line 57, in main
    client, addr = s.accept()
  File "/usr/lib/python3.9/socket.py", line 293, in accept
    fd, addr = self._accept()
socket.timeout: timed out
2022-03-11 14:49:01,137 ERROR server Timeout exceeded
Traceback (most recent call last):
  File "/home/ota_sms_user/client-server-apps/lesson_7/server.py", line 57, in main
    client, addr = s.accept()
  File "/usr/lib/python3.9/socket.py", line 293, in accept
    fd, addr = self._accept()
socket.timeout: timed out
2022-03-11 14:49:11,348 ERROR server Timeout exceeded
Traceback (most recent call last):
  File "/home/ota_sms_user/client-server-apps/lesson_7/server.py", line 57, in main
    client, addr = s.accept()
  File "/usr/lib/python3.9/socket.py", line 293, in accept
    fd, addr = self._accept()
socket.timeout: timed out
2022-03-11 14:49:21,559 ERROR server Timeout exceeded
Traceback (most recent call last):
  File "/home/ota_sms_user/client-server-apps/lesson_7/server.py", line 57, in main
    client, addr = s.accept()
  File "/usr/lib/python3.9/socket.py", line 293, in accept
    fd, addr = self._accept()
socket.timeout: timed out
2022-03-11 14:49:31,771 ERROR server Timeout exceeded
Traceback (most recent call last):
  File "/home/ota_sms_user/client-server-apps/lesson_7/server.py", line 57, in main
    client, addr = s.accept()
  File "/usr/lib/python3.9/socket.py", line 293, in accept
    fd, addr = self._accept()
socket.timeout: timed out
2022-03-11 14:49:41,982 ERROR server Timeout exceeded
Traceback (most recent call last):
  File "/home/ota_sms_user/client-server-apps/lesson_7/server.py", line 57, in main
    client, addr = s.accept()
  File "/usr/lib/python3.9/socket.py", line 293, in accept
    fd, addr = self._accept()
socket.timeout: timed out
2022-03-11 14:49:52,192 ERROR server Timeout exceeded
Traceback (most recent call last):
  File "/home/ota_sms_user/client-server-apps/lesson_7/server.py", line 57, in main
    client, addr = s.accept()
  File "/usr/lib/python3.9/socket.py", line 293, in accept
    fd, addr = self._accept()
socket.timeout: timed out
2022-03-11 14:50:02,400 ERROR server Timeout exceeded
Traceback (most recent call last):
  File "/home/ota_sms_user/client-server-apps/lesson_7/server.py", line 57, in main
    client, addr = s.accept()
  File "/usr/lib/python3.9/socket.py", line 293, in accept
    fd, addr = self._accept()
socket.timeout: timed out
2022-03-11 14:50:12,610 ERROR server Timeout exceeded
Traceback (most recent call last):
  File "/home/ota_sms_user/client-server-apps/lesson_7/server.py", line 57, in main
    client, addr = s.accept()
  File "/usr/lib/python3.9/socket.py", line 293, in accept
    fd, addr = self._accept()
socket.timeout: timed out
2022-03-11 14:50:22,820 ERROR server Timeout exceeded
Traceback (most recent call last):
  File "/home/ota_sms_user/client-server-apps/lesson_7/server.py", line 57, in main
    client, addr = s.accept()
  File "/usr/lib/python3.9/socket.py", line 293, in accept
    fd, addr = self._accept()
socket.timeout: timed out
2022-03-11 14:50:33,028 ERROR server Timeout exceeded
Traceback (most recent call last):
  File "/home/ota_sms_user/client-server-apps/lesson_7/server.py", line 57, in main
    client, addr = s.accept()
  File "/usr/lib/python3.9/socket.py", line 293, in accept
    fd, addr = self._accept()
socket.timeout: timed out
2022-03-11 14:50:43,239 ERROR server Timeout exceeded
Traceback (most recent call last):
  File "/home/ota_sms_user/client-server-apps/lesson_7/server.py", line 57, in main
    client, addr = s.accept()
  File "/usr/lib/python3.9/socket.py", line 293, in accept
    fd, addr = self._accept()
socket.timeout: timed out
2022-03-11 14:50:53,448 ERROR server Timeout exceeded
Traceback (most recent call last):
  File "/home/ota_sms_user/client-server-apps/lesson_7/server.py", line 57, in main
    client, addr = s.accept()
  File "/usr/lib/python3.9/socket.py", line 293, in accept
    fd, addr = self._accept()
socket.timeout: timed out
2022-03-11 14:51:03,652 ERROR server Timeout exceeded
Traceback (most recent call last):
  File "/home/ota_sms_user/client-server-apps/lesson_7/server.py", line 57, in main
    client, addr = s.accept()
  File "/usr/lib/python3.9/socket.py", line 293, in accept
    fd, addr = self._accept()
socket.timeout: timed out
2022-03-11 14:51:13,863 ERROR server Timeout exceeded
Traceback (most recent call last):
  File "/home/ota_sms_user/client-server-apps/lesson_7/server.py", line 57, in main
    client, addr = s.accept()
  File "/usr/lib/python3.9/socket.py", line 293, in accept
    fd, addr = self._accept()
socket.timeout: timed out
2022-03-11 14:51:24,068 ERROR server Timeout exceeded
Traceback (most recent call last):
  File "/home/ota_sms_user/client-server-apps/lesson_7/server.py", line 57, in main
    client, addr = s.accept()
  File "/usr/lib/python3.9/socket.py", line 293, in accept
    fd, addr = self._accept()
socket.timeout: timed out
2022-03-11 14:51:34,280 ERROR server Timeout exceeded
Traceback (most recent call last):
  File "/home/ota_sms_user/client-server-apps/lesson_7/server.py", line 57, in main
    client, addr = s.accept()
  File "/usr/lib/python3.9/socket.py", line 293, in accept
    fd, addr = self._accept()
socket.timeout: timed out
2022-03-11 14:51:44,490 ERROR server Timeout exceeded
Traceback (most recent call last):
  File "/home/ota_sms_user/client-server-apps/lesson_7/server.py", line 57, in main
    client, addr = s.accept()
  File "/usr/lib/python3.9/socket.py", line 293, in accept
    fd, addr = self._accept()
socket.timeout: timed out
2022-03-11 14:51:54,694 ERROR server Timeout exceeded
Traceback (most recent call last):
  File "/home/ota_sms_user/client-server-apps/lesson_7/server.py", line 57, in main
    client, addr = s.accept()
  File "/usr/lib/python3.9/socket.py", line 293, in accept
    fd, addr = self._accept()
socket.timeout: timed out
2022-03-11 14:52:04,904 ERROR server Timeout exceeded
Traceback (most recent call last):
  File "/home/ota_sms_user/client-server-apps/lesson_7/server.py", line 57, in main
    client, addr = s.accept()
  File "/usr/lib/python3.9/socket.py", line 293, in accept
    fd, addr = self._accept()
socket.timeout: timed out
2022-03-11 14:52:15,110 ERROR server Timeout exceeded
Traceback (most recent call last):
  File "/home/ota_sms_user/client-server-apps/lesson_7/server.py", line 57, in main
    client, addr = s.accept()
  File "/usr/lib/python3.9/socket.py", line 293, in accept
    fd, addr = self._accept()
socket.timeout: timed out
2022-03-11 14:52:25,320 ERROR server Timeout exceeded
Traceback (most recent call last):
  File "/home/ota_sms_user/client-server-apps/lesson_7/server.py", line 57, in main
    client, addr = s.accept()
  File "/usr/lib/python3.9/socket.py", line 293, in accept
    fd, addr = self._accept()
socket.timeout: timed out
2022-03-11 14:52:35,531 ERROR server Timeout exceeded
Traceback (most recent call last):
  File "/home/ota_sms_user/client-server-apps/lesson_7/server.py", line 57, in main
    client, addr = s.accept()
  File "/usr/lib/python3.9/socket.py", line 293, in accept
    fd, addr = self._accept()
socket.timeout: timed out
2022-03-11 14:52:45,740 ERROR server Timeout exceeded
Traceback (most recent call last):
  File "/home/ota_sms_user/client-server-apps/lesson_7/server.py", line 57, in main
    client, addr = s.accept()
  File "/usr/lib/python3.9/socket.py", line 293, in accept
    fd, addr = self._accept()
socket.timeout: timed out
2022-03-11 14:52:55,949 ERROR server Timeout exceeded
Traceback (most recent call last):
  File "/home/ota_sms_user/client-server-apps/lesson_7/server.py", line 57, in main
    client, addr = s.accept()
  File "/usr/lib/python3.9/socket.py", line 293, in accept
    fd, addr = self._accept()
socket.timeout: timed out
2022-03-11 14:53:06,160 ERROR server Timeout exceeded
Traceback (most recent call last):
  File "/home/ota_sms_user/client-server-apps/lesson_7/server.py", line 57, in main
    client, addr = s.accept()
  File "/usr/lib/python3.9/socket.py", line 293, in accept
    fd, addr = self._accept()
socket.timeout: timed out
2022-03-11 14:53:16,372 ERROR server Timeout exceeded
Traceback (most recent call last):
  File "/home/ota_sms_user/client-server-apps/lesson_7/server.py", line 57, in main
    client, addr = s.accept()
  File "/usr/lib/python3.9/socket.py", line 293, in accept
    fd, addr = self._accept()
socket.timeout: timed out
2022-03-11 14:53:26,583 ERROR server Timeout exceeded
Traceback (most recent call last):
  File "/home/ota_sms_user/client-server-apps/lesson_7/server.py", line 57, in main
    client, addr = s.accept()
  File "/usr/lib/python3.9/socket.py", line 293, in accept
    fd, addr = self._accept()
socket.timeout: timed out
2022-03-11 14:53:36,792 ERROR server Timeout exceeded
Traceback (most recent call last):
  File "/home/ota_sms_user/client-server-apps/lesson_7/server.py", line 57, in main
    client, addr = s.accept()
  File "/usr/lib/python3.9/socket.py", line 293, in accept
    fd, addr = self._accept()
socket.timeout: timed out
2022-03-11 14:53:46,999 ERROR server Timeout exceeded
Traceback (most recent call last):
  File "/home/ota_sms_user/client-server-apps/lesson_7/server.py", line 57, in main
    client, addr = s.accept()
  File "/usr/lib/python3.9/socket.py", line 293, in accept
    fd, addr = self._accept()
socket.timeout: timed out
2022-03-11 14:53:57,208 ERROR server Timeout exceeded
Traceback (most recent call last):
  File "/home/ota_sms_user/client-server-apps/lesson_7/server.py", line 57, in main
    client, addr = s.accept()
  File "/usr/lib/python3.9/socket.py", line 293, in accept
    fd, addr = self._accept()
socket.timeout: timed out
2022-03-11 14:54:07,419 ERROR server Timeout exceeded
Traceback (most recent call last):
  File "/home/ota_sms_user/client-server-apps/lesson_7/server.py", line 57, in main
    client, addr = s.accept()
  File "/usr/lib/python3.9/socket.py", line 293, in accept
    fd, addr = self._accept()
socket.timeout: timed out
2022-03-11 14:54:17,628 ERROR server Timeout exceeded
Traceback (most recent call last):
  File "/home/ota_sms_user/client-server-apps/lesson_7/server.py", line 57, in main
    client, addr = s.accept()
  File "/usr/lib/python3.9/socket.py", line 293, in accept
    fd, addr = self._accept()
socket.timeout: timed out
2022-03-11 14:54:27,832 ERROR server Timeout exceeded
Traceback (most recent call last):
  File "/home/ota_sms_user/client-server-apps/lesson_7/server.py", line 57, in main
    client, addr = s.accept()
  File "/usr/lib/python3.9/socket.py", line 293, in accept
    fd, addr = self._accept()
socket.timeout: timed out
2022-03-11 14:54:38,040 ERROR server Timeout exceeded
Traceback (most recent call last):
  File "/home/ota_sms_user/client-server-apps/lesson_7/server.py", line 57, in main
    client, addr = s.accept()
  File "/usr/lib/python3.9/socket.py", line 293, in accept
    fd, addr = self._accept()
socket.timeout: timed out
2022-03-11 14:54:48,251 ERROR server Timeout exceeded
Traceback (most recent call last):
  File "/home/ota_sms_user/client-server-apps/lesson_7/server.py", line 57, in main
    client, addr = s.accept()
  File "/usr/lib/python3.9/socket.py", line 293, in accept
    fd, addr = self._accept()
socket.timeout: timed out
2022-03-11 14:54:58,462 ERROR server Timeout exceeded
Traceback (most recent call last):
  File "/home/ota_sms_user/client-server-apps/lesson_7/server.py", line 57, in main
    client, addr = s.accept()
  File "/usr/lib/python3.9/socket.py", line 293, in accept
    fd, addr = self._accept()
socket.timeout: timed out
2022-03-11 14:55:08,672 ERROR server Timeout exceeded
Traceback (most recent call last):
  File "/home/ota_sms_user/client-server-apps/lesson_7/server.py", line 57, in main
    client, addr = s.accept()
  File "/usr/lib/python3.9/socket.py", line 293, in accept
    fd, addr = self._accept()
socket.timeout: timed out
2022-03-11 14:55:18,880 ERROR server Timeout exceeded
Traceback (most recent call last):
  File "/home/ota_sms_user/client-server-apps/lesson_7/server.py", line 57, in main
    client, addr = s.accept()
  File "/usr/lib/python3.9/socket.py", line 293, in accept
    fd, addr = self._accept()
socket.timeout: timed out
2022-03-11 14:55:29,089 ERROR server Timeout exceeded
Traceback (most recent call last):
  File "/home/ota_sms_user/client-server-apps/lesson_7/server.py", line 57, in main
    client, addr = s.accept()
  File "/usr/lib/python3.9/socket.py", line 293, in accept
    fd, addr = self._accept()
socket.timeout: timed out
2022-03-11 14:55:39,300 ERROR server Timeout exceeded
Traceback (most recent call last):
  File "/home/ota_sms_user/client-server-apps/lesson_7/server.py", line 57, in main
    client, addr = s.accept()
  File "/usr/lib/python3.9/socket.py", line 293, in accept
    fd, addr = self._accept()
socket.timeout: timed out
2022-03-11 14:55:49,503 ERROR server Timeout exceeded
Traceback (most recent call last):
  File "/home/ota_sms_user/client-server-apps/lesson_7/server.py", line 57, in main
    client, addr = s.accept()
  File "/usr/lib/python3.9/socket.py", line 293, in accept
    fd, addr = self._accept()
socket.timeout: timed out
2022-03-11 14:55:59,712 ERROR server Timeout exceeded
Traceback (most recent call last):
  File "/home/ota_sms_user/client-server-apps/lesson_7/server.py", line 57, in main
    client, addr = s.accept()
  File "/usr/lib/python3.9/socket.py", line 293, in accept
    fd, addr = self._accept()
socket.timeout: timed out
2022-03-11 14:56:09,923 ERROR server Timeout exceeded
Traceback (most recent call last):
  File "/home/ota_sms_user/client-server-apps/lesson_7/server.py", line 57, in main
    client, addr = s.accept()
  File "/usr/lib/python3.9/socket.py", line 293, in accept
    fd, addr = self._accept()
socket.timeout: timed out
2022-03-11 14:56:20,132 ERROR server Timeout exceeded
Traceback (most recent call last):
  File "/home/ota_sms_user/client-server-apps/lesson_7/server.py", line 57, in main
    client, addr = s.accept()
  File "/usr/lib/python3.9/socket.py", line 293, in accept
    fd, addr = self._accept()
socket.timeout: timed out
2022-03-11 14:56:30,342 ERROR server Timeout exceeded
Traceback (most recent call last):
  File "/home/ota_sms_user/client-server-apps/lesson_7/server.py", line 57, in main
    client, addr = s.accept()
  File "/usr/lib/python3.9/socket.py", line 293, in accept
    fd, addr = self._accept()
socket.timeout: timed out
2022-03-11 14:56:40,554 ERROR server Timeout exceeded
Traceback (most recent call last):
  File "/home/ota_sms_user/client-server-apps/lesson_7/server.py", line 57, in main
    client, addr = s.accept()
  File "/usr/lib/python3.9/socket.py", line 293, in accept
    fd, addr = self._accept()
socket.timeout: timed out
2022-03-11 14:56:50,764 ERROR server Timeout exceeded
Traceback (most recent call last):
  File "/home/ota_sms_user/client-server-apps/lesson_7/server.py", line 57, in main
    client, addr = s.accept()
  File "/usr/lib/python3.9/socket.py", line 293, in accept
    fd, addr = self._accept()
socket.timeout: timed out
2022-03-11 14:57:00,972 ERROR server Timeout exceeded
Traceback (most recent call last):
  File "/home/ota_sms_user/client-server-apps/lesson_7/server.py", line 57, in main
    client, addr = s.accept()
  File "/usr/lib/python3.9/socket.py", line 293, in accept
    fd, addr = self._accept()
socket.timeout: timed out
2022-03-11 14:57:11,180 ERROR server Timeout exceeded
Traceback (most recent call last):
  File "/home/ota_sms_user/client-server-apps/lesson_7/server.py", line 57, in main
    client, addr = s.accept()
  File "/usr/lib/python3.9/socket.py", line 293, in accept
    fd, addr = self._accept()
socket.timeout: timed out
2022-03-11 14:57:21,389 ERROR server Timeout exceeded
Traceback (most recent call last):
  File "/home/ota_sms_user/client-server-apps/lesson_7/server.py", line 57, in main
    client, addr = s.accept()
  File "/usr/lib/python3.9/socket.py", line 293, in accept
    fd, addr = self._accept()
socket.timeout: timed out
2022-03-11 14:57:31,596 ERROR server Timeout exceeded
Traceback (most recent call last):
  File "/home/ota_sms_user/client-server-apps/lesson_7/server.py", line 57, in main
    client, addr = s.accept()
  File "/usr/lib/python3.9/socket.py", line 293, in accept
    fd, addr = self._accept()
socket.timeout: timed out
2022-03-11 14:57:41,805 ERROR server Timeout exceeded
Traceback (most recent call last):
  File "/home/ota_sms_user/client-server-apps/lesson_7/server.py", line 57, in main
    client, addr = s.accept()
  File "/usr/lib/python3.9/socket.py", line 293, in accept
    fd, addr = self._accept()
socket.timeout: timed out
2022-03-11 14:57:52,016 ERROR server Timeout exceeded
Traceback (most recent call last):
  File "/home/ota_sms_user/client-server-apps/lesson_7/server.py", line 57, in main
    client, addr = s.accept()
  File "/usr/lib/python3.9/socket.py", line 293, in accept
    fd, addr = self._accept()
socket.timeout: timed out
2022-03-11 14:58:02,224 ERROR server Timeout exceeded
Traceback (most recent call last):
  File "/home/ota_sms_user/client-server-apps/lesson_7/server.py", line 57, in main
    client, addr = s.accept()
  File "/usr/lib/python3.9/socket.py", line 293, in accept
    fd, addr = self._accept()
socket.timeout: timed out
2022-03-11 14:58:12,432 ERROR server Timeout exceeded
Traceback (most recent call last):
  File "/home/ota_sms_user/client-server-apps/lesson_7/server.py", line 57, in main
    client, addr = s.accept()
  File "/usr/lib/python3.9/socket.py", line 293, in accept
    fd, addr = self._accept()
socket.timeout: timed out
2022-03-11 14:58:22,639 ERROR server Timeout exceeded
Traceback (most recent call last):
  File "/home/ota_sms_user/client-server-apps/lesson_7/server.py", line 57, in main
    client, addr = s.accept()
  File "/usr/lib/python3.9/socket.py", line 293, in accept
    fd, addr = self._accept()
socket.timeout: timed out
2022-03-11 14:58:25,740 ERROR server Timeout exceeded
Traceback (most recent call last):
  File "/home/ota_sms_user/client-server-apps/lesson_7/server.py", line 57, in main
    client, addr = s.accept()
  File "/usr/lib/python3.9/socket.py", line 293, in accept
    fd, addr = self._accept()
socket.timeout: timed out
2022-03-11 14:58:35,948 ERROR server Timeout exceeded
Traceback (most recent call last):
  File "/home/ota_sms_user/client-server-apps/lesson_7/server.py", line 57, in main
    client, addr = s.accept()
  File "/usr/lib/python3.9/socket.py", line 293, in accept
    fd, addr = self._accept()
socket.timeout: timed out
2022-03-11 14:58:40,294 INFO server Server is running on localhost:7777
2022-03-11 15:00:01,960 DEBUG server New client: ('127.0.0.1', 53944)
2022-03-11 15:19:25,059 INFO server Server is running on localhost:7777
2022-03-11 15:19:35,268 DEBUG server New client: ('127.0.0.1', 53982)
2022-03-11 15:19:35,268 INFO server Client 5 ('127.0.0.1', 53982) was disconnected.
2022-03-11 15:20:41,452 INFO server Server is running on localhost:7777
2022-03-11 15:20:43,856 DEBUG server New client: ('127.0.0.1', 53984)
2022-03-11 15:20:43,856 INFO server Client 5 ('127.0.0.1', 53984) was disconnected.
2022-03-11 15:21:27,166 INFO server Server is running on localhost:7777
2022-03-11 15:21:28,373 DEBUG server New client: ('127.0.0.1', 53986)
2022-03-11 15:21:28,775 INFO server Client 5 ('127.0.0.1', 53986) was disconnected.
2022-03-11 15:24:31,394 DEBUG server New client: ('127.0.0.1', 53990)
2022-03-11 15:24:31,594 INFO server Client 6 ('127.0.0.1', 53990) was disconnected.
2022-03-11 15:24:47,210 DEBUG server New client: ('127.0.0.1', 53992)
2022-03-11 15:24:47,411 INFO server Client 5 ('127.0.0.1', 53992) was disconnected.
2022-03-11 15:24:49,979 DEBUG server New client: ('127.0.0.1', 53998)
2022-03-11 15:32:14,804 INFO server Server is running on localhost:7777
2022-03-11 15:32:17,206 DEBUG server New client: ('127.0.0.1', 54012)
2022-03-11 15:32:17,207 INFO server Client 5 ('127.0.0.1', 54012) was disconnected.
2022-03-11 15:34:01,058 INFO server Server is running on localhost:7777
2022-03-11 15:34:03,461 DEBUG server New client: ('127.0.0.1', 54014)
2022-03-11 15:34:03,461 ERROR server Is message a dict?
Traceback (most recent call last):
  File "/home/ota_sms_user/client-server-apps/lesson_7/server.py", line 49, in write_responses
    send_message(sock, client_message['msg'])
  File "/home/ota_sms_user/client-server-apps/lesson_7/common/utils.py", line 12, in send_message
    raise TypeError
TypeError
2022-03-11 15:35:07,450 INFO server Server is running on localhost:7777
2022-03-11 15:35:11,055 DEBUG server New client: ('127.0.0.1', 54016)
2022-03-11 15:35:11,256 INFO server Client 5 ('127.0.0.1', 54016) was disconnected.
2022-03-11 15:35:47,261 INFO server Server is running on localhost:7777
2022-03-11 15:35:49,664 DEBUG server New client: ('127.0.0.1', 54018)
2022-03-11 15:35:49,865 INFO server Client 5 ('127.0.0.1', 54018) was disconnected.
2022-03-11 15:37:32,363 DEBUG server New client: ('127.0.0.1', 54020)
2022-03-11 15:37:32,764 INFO server Client 6 ('127.0.0.1', 54020) was disconnected.
2022-03-11 15:38:00,397 DEBUG server New client: ('127.0.0.1', 54024)
2022-03-11 15:38:33,321 DEBUG server New client: ('127.0.0.1', 54026)
2022-03-11 15:38:33,468 INFO server Server is running on localhost:7777
2022-03-11 15:38:40,678 DEBUG server New client: ('127.0.0.1', 54028)
2022-03-11 15:41:58,684 DEBUG server New client: ('127.0.0.1', 54030)
2022-03-11 15:42:03,219 INFO server Server is running on localhost:7777
2022-03-11 15:42:04,526 DEBUG server New client: ('127.0.0.1', 54032)
2022-03-11 15:42:25,953 DEBUG server New client: ('127.0.0.1', 54034)
2022-03-11 15:42:39,472 INFO server Server is running on localhost:7777
2022-03-11 15:42:41,876 DEBUG server New client: ('127.0.0.1', 54036)
2022-03-11 15:42:44,245 DEBUG server New client: ('127.0.0.1', 54038)
2022-03-11 15:44:58,370 INFO server Server is running on localhost:7777
2022-03-11 15:45:00,773 DEBUG server New client: ('127.0.0.1', 54040)
2022-03-11 15:46:51,464 INFO server Server is running on localhost:7777
2022-03-11 15:46:53,867 DEBUG server New client: ('127.0.0.1', 54050)
2022-03-11 15:47:32,731 INFO server Client 5 ('127.0.0.1', 54050) was disconnected.
2022-03-11 15:47:37,535 DEBUG server New client: ('127.0.0.1', 54052)
2022-03-11 15:48:23,067 INFO server Server is running on localhost:7777
2022-03-11 15:48:24,321 DEBUG server New client: ('127.0.0.1', 54054)
2022-03-11 15:49:08,906 INFO server Server is running on localhost:7777
2022-03-11 15:49:10,151 DEBUG server New client: ('127.0.0.1', 54056)
2022-03-11 15:53:41,756 INFO server Server is running on localhost:7777
2022-03-11 15:53:42,958 DEBUG server New client: ('127.0.0.1', 54280)
2022-03-11 16:02:15,218 INFO server Server is running on localhost:7777
2022-03-11 16:02:17,621 DEBUG server New client: ('127.0.0.1', 54536)
2022-03-11 16:02:23,940 DEBUG server New client: ('127.0.0.1', 54538)
2022-03-11 16:02:23,941 INFO server Client 5 ('127.0.0.1', 54536) was disconnected.
2022-03-11 16:04:06,071 DEBUG server New client: ('127.0.0.1', 54542)
2022-03-11 16:05:50,432 DEBUG server New client: ('127.0.0.1', 54544)
2022-03-11 16:05:50,432 INFO server Client 6 ('127.0.0.1', 54538) was disconnected.
2022-03-11 16:06:47,736 INFO server Client 5 ('127.0.0.1', 54542) was disconnected.
2022-03-11 16:06:53,775 DEBUG server New client: ('127.0.0.1', 54546)
2022-03-11 16:06:54,377 INFO server Client 5 ('127.0.0.1', 54546) was disconnected.
2022-03-11 16:06:56,161 DEBUG server New client: ('127.0.0.1', 54548)
2022-03-11 16:07:06,581 INFO server Client 7 ('127.0.0.1', 54544) was disconnected.
2022-03-11 16:07:06,630 DEBUG server New client: ('127.0.0.1', 54550)
2022-03-11 16:07:36,295 INFO server Client 5 ('127.0.0.1', 54550) was disconnected.
2022-03-11 16:07:38,746 DEBUG server New client: ('127.0.0.1', 54552)
2022-03-11 16:08:22,424 INFO server Client 6 ('127.0.0.1', 54548) was disconnected.
2022-03-11 16:08:23,999 DEBUG server New client: ('127.0.0.1', 54554)
2022-03-11 16:08:56,639 INFO server Server is running on localhost:7777
2022-03-11 16:08:59,041 DEBUG server New client: ('127.0.0.1', 54556)
2022-03-11 16:09:07,282 DEBUG server New client: ('127.0.0.1', 54558)
2022-03-11 16:10:36,509 INFO server Server is running on localhost:7777
2022-03-11 16:10:40,113 DEBUG server New client: ('127.0.0.1', 54568)
2022-03-11 16:10:47,725 INFO server Client 5 ('127.0.0.1', 54568) was disconnected.
2022-03-11 16:10:47,766 DEBUG server New client: ('127.0.0.1', 54572)
2022-03-11 16:10:56,543 DEBUG server New client: ('127.0.0.1', 54574)
2022-03-11 16:11:22,806 INFO server Client 5 ('127.0.0.1', 54574) was disconnected.
2022-03-11 16:11:48,395 DEBUG server New client: ('127.0.0.1', 54576)
2022-03-11 16:11:50,798 INFO server Client 7 ('127.0.0.1', 54576) was disconnected.
2022-03-11 16:11:54,655 DEBUG server New client: ('127.0.0.1', 54578)
2022-03-11 16:13:04,948 INFO server Client 5 ('127.0.0.1', 54578) was disconnected.
2022-03-11 16:13:10,533 INFO server Server is running on localhost:7777
2022-03-11 16:13:12,935 DEBUG server New client: ('127.0.0.1', 54580)
2022-03-11 16:13:17,177 DEBUG server New client: ('127.0.0.1', 54582)
2022-03-11 16:19:50,853 INFO server Server is running on localhost:7777
2022-03-11 16:19:55,659 DEBUG server New client: ('127.0.0.1', 54860)
2022-03-11 16:20:03,184 DEBUG server New client: ('127.0.0.1', 54862)
2022-03-11 16:22:00,940 INFO server Server is running on localhost:7777
2022-03-11 16:22:03,343 DEBUG server New client: ('127.0.0.1', 54866)
2022-03-11 16:22:18,448 DEBUG server New client: ('127.0.0.1', 54868)
2022-03-11 16:24:55,547 INFO server Client 6 ('127.0.0.1', 54868) was disconnected.
2022-03-11 16:25:06,932 DEBUG server New client: ('127.0.0.1', 54872)
2022-03-11 16:25:08,736 INFO server Client 7 ('127.0.0.1', 54872) was disconnected.
